<?xml version="1.0" encoding="utf-8"?>
<robot name="whagv5_5">
  <link name="base_link">
    <visual>
      <geometry>
        <mesh filename="../meshes/simplified/cover.dae" scale="1 1 1"/>
      </geometry>
    </visual>
    <collision>
      <geometry>
        <mesh filename="../meshes/simplified/cover.dae" scale="1 1 1"/>
      </geometry>
    </collision>
    <inertial>
      <origin rpy="0 0 0" xyz="0 0 0.1"/>
      <mass value="100"/>
      <inertia ixx="0.045" ixy="0" ixz="0" iyy="0.179" iyz="0" izz="0.194"/>
    </inertial>
  </link>
  <link name="omniwheel_front_right">
    <visual>
      <geometry>
        <mesh filename="../meshes/simplified/omniwheel.dae" scale="1 1 1"/>
      </geometry>
    </visual>
    <collision>
      <geometry>
        <mesh filename="../meshes/simplified/omniwheel.dae" scale="1 1 1"/>
      </geometry>
    </collision>
    <inertial>
      <origin rpy="0 0 0" xyz="0 0 0"/>
      <mass value="5"/>
      <inertia ixx="0.004" ixy="0" ixz="0" iyy="0.004" iyz="0" izz="0.004"/>
    </inertial>
  </link>
  <joint name="omniwheel_front_right_joint" type="continuous">
    <parent link="base_link"/>
    <child link="omniwheel_front_right"/>
    <origin rpy="0 0 0" xyz="0.36 0.3 0.0725"/>
    <axis xyz="0 1 0"/>
  </joint>
  <link name="omniwheel_front_left">
    <visual>
      <geometry>
        <mesh filename="../meshes/simplified/omniwheel.dae" scale="1 1 1"/>
      </geometry>
    </visual>
    <collision>
      <geometry>
        <mesh filename="../meshes/simplified/omniwheel.dae" scale="1 1 1"/>
      </geometry>
    </collision>
    <inertial>
      <origin rpy="0 0 0" xyz="0 0 0"/>
      <mass value="5"/>
      <inertia ixx="0.004" ixy="0" ixz="0" iyy="0.004" iyz="0" izz="0.004"/>
    </inertial>
  </link>
  <joint name="omniwheel_front_left_joint" type="continuous">
    <parent link="base_link"/>
    <child link="omniwheel_front_left"/>
    <origin rpy="0 0 0" xyz="0.36 -0.3 0.0725"/>
    <axis xyz="0 1 0"/>
  </joint>
  <link name="omniwheel_back_right">
    <visual>
      <geometry>
        <mesh filename="../meshes/simplified/omniwheel.dae" scale="1 1 1"/>
      </geometry>
    </visual>
    <collision>
      <geometry>
        <mesh filename="../meshes/simplified/omniwheel.dae" scale="1 1 1"/>
      </geometry>
    </collision>
    <inertial>
      <origin rpy="0 0 0" xyz="0 0 0"/>
      <mass value="5"/>
      <inertia ixx="0.004" ixy="0" ixz="0" iyy="0.004" iyz="0" izz="0.004"/>
    </inertial>
  </link>
  <joint name="omniwheel_back_right_joint" type="continuous">
    <parent link="base_link"/>
    <child link="omniwheel_back_right"/>
    <origin rpy="0 0 0" xyz="-0.36 0.3 0.0725"/>
    <axis xyz="0 1 0"/>
  </joint>
  <link name="omniwheel_back_left">
    <visual>
      <geometry>
        <mesh filename="../meshes/simplified/omniwheel.dae" scale="1 1 1"/>
      </geometry>
    </visual>
    <collision>
      <geometry>
        <mesh filename="../meshes/simplified/omniwheel.dae" scale="1 1 1"/>
      </geometry>
    </collision>
    <inertial>
      <origin rpy="0 0 0" xyz="0 0 0"/>
      <mass value="5"/>
      <inertia ixx="0.004" ixy="0" ixz="0" iyy="0.004" iyz="0" izz="0.004"/>
    </inertial>
  </link>
  <joint name="omniwheel_back_left_joint" type="continuous">
    <parent link="base_link"/>
    <child link="omniwheel_back_left"/>
    <origin rpy="0 0 0" xyz="-0.36 -0.3 0.0725"/>
    <axis xyz="0 1 0"/>
  </joint>
  <link name="laser_horizontal_front_link">
    <visual>
      <origin xyz="0 0 0"/>
      <geometry>
        <cylinder length="0.05" radius="0.03"/>
      </geometry>
      <material name="orange"/>
    </visual>
    <inertial>
      <mass value="0.1"/>
      <inertia ixx="0.1" ixy="0" ixz="0" iyy="0.1" iyz="0" izz="0.1"/>
    </inertial>
  </link>
  <joint name="laser_horizontal_front_joint" type="fixed">
    <parent link="base_link"/>
    <child link="laser_horizontal_front_link"/>
    <origin rpy="3.141592653589793 0 0.58" xyz="0.404 0.285 0.25"/>
  </joint>
  <gazebo reference="laser_horizontal_front_link">
    <material>Gazebo/Orange</material>
    <sensor name="horizontal_front_hokuyo_sensor" type="ray">
      <pose>0.025 0 0.1 0 0 0</pose>
      <visualize>false</visualize>
      <update_rate>33.34</update_rate>
      <ray>
        <scan>
          <horizontal>
            <samples>1080</samples>
            <resolution>1</resolution>
            <min_angle>-2.2689280275926285</min_angle>
            <max_angle>2.2689280275926285</max_angle>
          </horizontal>
        </scan>
        <range>
          <min>0.05</min>
          <max>30.0</max>
          <resolution>0.001</resolution>
        </range>
        <noise>
          <type>gaussian</type>
          <mean>0.0</mean>
          <stddev>0.01</stddev>
        </noise>
      </ray>
      <plugin filename="libgazebo_ros_laser.so" name="gazebo_ros_head_hokuyo_controller">
        <topicName>/laser_horizontal_front</topicName>
        <frameName>laser_horizontal_front_link</frameName>
      </plugin>
    </sensor>
  </gazebo>
  <link name="laser_horizontal_rear_link">
    <visual>
      <origin xyz="0 0 0"/>
      <geometry>
        <cylinder length="0.05" radius="0.03"/>
      </geometry>
      <material name="orange"/>
    </visual>
    <inertial>
      <mass value="0.1"/>
      <inertia ixx="0.1" ixy="0" ixz="0" iyy="0.1" iyz="0" izz="0.1"/>
    </inertial>
  </link>
  <joint name="laser_horizontal_rear_joint" type="fixed">
    <parent link="base_link"/>
    <child link="laser_horizontal_rear_link"/>
    <origin rpy="3.141592653589793 0 -2.5" xyz="-0.404 -0.285 0.25"/>
  </joint>
  <gazebo reference="laser_horizontal_rear_link">
    <material>Gazebo/Orange</material>
    <sensor name="horizontal_rear_hokuyo_sensor" type="ray">
      <pose>0.025 0 0.1 0 0 0</pose>
      <visualize>false</visualize>
      <update_rate>33.34</update_rate>
      <ray>
        <scan>
          <horizontal>
            <samples>1080</samples>
            <resolution>1</resolution>
            <min_angle>-2.2689280275926285</min_angle>
            <max_angle>2.2689280275926285</max_angle>
          </horizontal>
        </scan>
        <range>
          <min>0.05</min>
          <max>30.0</max>
          <resolution>0.001</resolution>
        </range>
        <noise>
          <type>gaussian</type>
          <mean>0.0</mean>
          <stddev>0.01</stddev>
        </noise>
      </ray>
      <plugin filename="libgazebo_ros_laser.so" name="gazebo_ros_head_hokuyo_controller">
        <topicName>/laser_horizontal_rear</topicName>
        <frameName>laser_horizontal_rear_link</frameName>
      </plugin>
    </sensor>
  </gazebo>
  <joint name="arm_base_joint" type="fixed">
    <parent link="base_link"/>
    <child link="arm_base_link"/>
    <origin rpy="0 0 -1.5707963267948966" xyz="0.253 0 0.64"/>
  </joint>
  <link name="arm_base_link">
    <visual>
      <origin rpy="0 0 0" xyz="0 0 0"/>
      <geometry>
        <mesh filename="../meshes/yaskawa_robot_arm/base.dae"/>
      </geometry>
    </visual>
    <inertial>
      <origin xyz="0 0 0.0575"/>
      <mass value="2"/>
      <inertia ixx="0.00440833333333" ixy="0" ixz="0" iyy="0.00440833333333" iyz="0" izz="0.00440833333333"/>
    </inertial>
  </link>
  <link name="arm_s_axis_link">
    <visual>
      <origin rpy="0 1.57079632679 0" xyz="0 0 0"/>
      <geometry>
        <mesh filename="../meshes/yaskawa_robot_arm/s_axis.dae"/>
      </geometry>
    </visual>
    <inertial>
      <origin rpy="0 0 3.14159265359" xyz="-0.06 0 0.06"/>
      <mass value="2"/>
      <inertia ixx="0.0048" ixy="0" ixz="0" iyy="0.0048" iyz="0" izz="0.0048"/>
    </inertial>
  </link>
  <joint name="arm_s_axis_joint" type="continuous">
    <parent link="arm_base_link"/>
    <child link="arm_s_axis_link"/>
    <origin rpy="1.57079632679 -1.57079632679 0" xyz="0 0 0.115"/>
  </joint>
  <transmission name="arm_s_axis_trans">
    <type>transmission_interface/SimpleTransmission</type>
    <joint name="arm_s_axis_joint">
      <hardwareInterface>hardware_interface/EffortJointInterface</hardwareInterface>
    </joint>
    <actuator name="arm_s_axis_motor">
      <hardwareInterface>hardware_interface/EffortJointInterface</hardwareInterface>
      <mechanicalReduction>1</mechanicalReduction>
    </actuator>
  </transmission>
  <link name="arm_l_axis_link">
    <visual>
      <origin rpy="0 0 0" xyz="0 0 0"/>
      <geometry>
        <mesh filename="../meshes/yaskawa_robot_arm/l_axis.dae"/>
      </geometry>
    </visual>
    <inertial>
      <origin xyz="0 0 0.35"/>
      <mass value="2"/>
      <inertia ixx="0.0829166666667" ixy="0" ixz="0" iyy="0.0829166666667" iyz="0" izz="0.0829166666667"/>
    </inertial>
  </link>
  <joint name="arm_l_axis_joint" type="continuous">
    <parent link="arm_s_axis_link"/>
    <child link="arm_l_axis_link"/>
    <origin rpy="0 1.57079632679 0" xyz="0.135 0 0.134"/>
  </joint>
  <transmission name="arm_l_axis_trans">
    <type>transmission_interface/SimpleTransmission</type>
    <joint name="arm_l_axis_joint">
      <hardwareInterface>hardware_interface/EffortJointInterface</hardwareInterface>
    </joint>
    <actuator name="arm_l_axis_motor">
      <hardwareInterface>hardware_interface/EffortJointInterface</hardwareInterface>
      <mechanicalReduction>1</mechanicalReduction>
    </actuator>
  </transmission>
  <link name="arm_u_axis_link">
    <visual>
      <origin rpy="0 3.14159265359 0" xyz="0 0 0"/>
      <geometry>
        <mesh filename="../meshes/yaskawa_robot_arm/u_axis.dae"/>
      </geometry>
    </visual>
    <inertial>
      <origin xyz="0.05 0 -0.05"/>
      <mass value="1"/>
      <inertia ixx="0.00166666666667" ixy="0" ixz="0" iyy="0.00166666666667" iyz="0" izz="0.00166666666667"/>
    </inertial>
  </link>
  <joint name="arm_u_axis_joint" type="continuous">
    <parent link="arm_l_axis_link"/>
    <child link="arm_u_axis_link"/>
    <origin rpy="0 3.14159265359 0" xyz="0.014 0 0.7"/>
  </joint>
  <transmission name="arm_u_axis_trans">
    <type>transmission_interface/SimpleTransmission</type>
    <joint name="arm_u_axis_joint">
      <hardwareInterface>hardware_interface/EffortJointInterface</hardwareInterface>
    </joint>
    <actuator name="arm_u_axis_motor">
      <hardwareInterface>hardware_interface/EffortJointInterface</hardwareInterface>
      <mechanicalReduction>1</mechanicalReduction>
    </actuator>
  </transmission>
  <link name="arm_r_axis_link">
    <visual>
      <origin rpy="3.14159265359 -1.57079632679 0" xyz="0 0 0"/>
      <geometry>
        <mesh filename="../meshes/yaskawa_robot_arm/r_axis.dae"/>
      </geometry>
    </visual>
    <inertial>
      <origin xyz="-0.03 0 0.19"/>
      <mass value="0.5"/>
      <inertia ixx="0.00632916666667" ixy="0" ixz="0" iyy="0.00632916666667" iyz="0" izz="0.00632916666667"/>
    </inertial>
  </link>
  <joint name="arm_r_axis_joint" type="continuous">
    <parent link="arm_u_axis_link"/>
    <child link="arm_r_axis_link"/>
    <origin rpy="3.14159265359 1.57079632679 0" xyz="-0.119 0 0.130"/>
  </joint>
  <transmission name="arm_r_axis_trans">
    <type>transmission_interface/SimpleTransmission</type>
    <joint name="arm_r_axis_joint">
      <hardwareInterface>hardware_interface/EffortJointInterface</hardwareInterface>
    </joint>
    <actuator name="arm_r_axis_motor">
      <hardwareInterface>hardware_interface/EffortJointInterface</hardwareInterface>
      <mechanicalReduction>1</mechanicalReduction>
    </actuator>
  </transmission>
  <link name="arm_b_axis_link">
    <visual>
      <origin rpy="-1.57079632679 3.14159265359 0" xyz="0 0 0"/>
      <geometry>
        <mesh filename="../meshes/yaskawa_robot_arm/b_axis.dae"/>
      </geometry>
    </visual>
    <inertial>
      <origin xyz="0.05 0.045 0"/>
      <mass value="0.2"/>
      <inertia ixx="0.00026" ixy="0" ixz="0" iyy="0.00026" iyz="0" izz="0.00026"/>
    </inertial>
  </link>
  <joint name="arm_b_axis_joint" type="continuous">
    <parent link="arm_r_axis_link"/>
    <child link="arm_b_axis_link"/>
    <!-- <origin rpy="-${pi / 2} 0 0" xyz="0.05 0 -0.38" /> -->
    <origin rpy="3.14159265359 1.57079632679 0" xyz="-0.368 0 0.04"/>
  </joint>
  <transmission name="arm_b_axis_trans">
    <type>transmission_interface/SimpleTransmission</type>
    <joint name="arm_b_axis_joint">
      <hardwareInterface>hardware_interface/EffortJointInterface</hardwareInterface>
    </joint>
    <actuator name="arm_b_axis_motor">
      <hardwareInterface>hardware_interface/EffortJointInterface</hardwareInterface>
      <mechanicalReduction>1</mechanicalReduction>
    </actuator>
  </transmission>
  <link name="arm_t_axis_link">
    <visual>
      <origin rpy="0 0 -1.57079632679" xyz="0 0 0"/>
      <geometry>
        <mesh filename="../meshes/yaskawa_robot_arm/t_axis.dae"/>
      </geometry>
    </visual>
    <inertial>
      <origin xyz="0.05 0 0"/>
      <mass value="0.1"/>
      <inertia ixx="4.16666666667e-05" ixy="0" ixz="0" iyy="4.16666666667e-05" iyz="0" izz="4.16666666667e-05"/>
    </inertial>
  </link>
  <joint name="arm_t_axis_joint" type="continuous">
    <parent link="arm_b_axis_link"/>
    <child link="arm_t_axis_link"/>
    <origin rpy="1.57079632679 1.57079632679 0" xyz="-0.121 0 0.05"/>
    <axis rpy="0 0 0" xyz="-1 0 0"/>
  </joint>
  <transmission name="arm_t_axis_trans">
    <type>transmission_interface/SimpleTransmission</type>
    <joint name="arm_t_axis_joint">
      <hardwareInterface>hardware_interface/EffortJointInterface</hardwareInterface>
    </joint>
    <actuator name="arm_t_axis_motor">
      <hardwareInterface>hardware_interface/EffortJointInterface</hardwareInterface>
      <mechanicalReduction>1</mechanicalReduction>
    </actuator>
  </transmission>
  <link name="arm_gripper_left_link">
    <visual>
      <origin rpy="0 0 -1.57079632679" xyz="0 0 0"/>
      <geometry>
        <mesh filename="../meshes/yaskawa_robot_arm/gripper_left.dae"/>
      </geometry>
    </visual>
    <inertial>
      <origin xyz="0.05 0 0"/>
      <mass value="0.1"/>
      <inertia ixx="4.16666666667e-05" ixy="0" ixz="0" iyy="4.16666666667e-05" iyz="0" izz="4.16666666667e-05"/>
    </inertial>
  </link>
  <joint name="arm_gripper_left_axis_joint" type="prismatic">
    <parent link="arm_t_axis_link"/>
    <child link="arm_gripper_left_link"/>
    <origin rpy="0 0 0" xyz="0 0 0"/>
    <axis xyz="0 1 0"/>
    <limit effort="1000.0" lower="-0.05" upper="0.03" velocity="0.5"/>
  </joint>
  <transmission name="arm_gripper_left_trans">
    <type>transmission_interface/SimpleTransmission</type>
    <joint name="arm_gripper_left_axis_joint">
      <hardwareInterface>hardware_interface/EffortJointInterface</hardwareInterface>
    </joint>
    <actuator name="arm_gripper_left_motor">
      <hardwareInterface>hardware_interface/EffortJointInterface</hardwareInterface>
      <mechanicalReduction>1</mechanicalReduction>
    </actuator>
  </transmission>
  <link name="arm_gripper_right_link">
    <visual>
      <origin rpy="0 0 -1.57079632679" xyz="0 0 0"/>
      <geometry>
        <mesh filename="../meshes/yaskawa_robot_arm/gripper_right.dae"/>
      </geometry>
    </visual>
    <inertial>
      <origin xyz="0.05 0 0"/>
      <mass value="0.1"/>
      <inertia ixx="4.16666666667e-05" ixy="0" ixz="0" iyy="4.16666666667e-05" iyz="0" izz="4.16666666667e-05"/>
    </inertial>
  </link>
  <joint name="arm_gripper_right_axis_joint" type="prismatic">
    <parent link="arm_t_axis_link"/>
    <child link="arm_gripper_right_link"/>
    <origin rpy="0 0 0" xyz="0 0 0"/>
    <axis xyz="0 1 0"/>
    <limit effort="1000.0" lower="-0.03" upper="0.05" velocity="0.5"/>
  </joint>
  <transmission name="arm_gripper_right_trans">
    <type>transmission_interface/SimpleTransmission</type>
    <joint name="arm_gripper_right_axis_joint">
      <hardwareInterface>hardware_interface/EffortJointInterface</hardwareInterface>
    </joint>
    <actuator name="arm_gripper_right_motor">
      <hardwareInterface>hardware_interface/EffortJointInterface</hardwareInterface>
      <mechanicalReduction>1</mechanicalReduction>
    </actuator>
  </transmission>
  <gazebo>
    <plugin filename="libgazebo_ros_control.so" name="gazebo_ros_control">
      <robotNamespace>/yaskawa_arm</robotNamespace>
      <legacyModeNS>true</legacyModeNS>
    </plugin>
  </gazebo>
</robot>
